Workbook

Sheet Project Data
A1: Project Name | B1: Backup Cluster Manager SEP
A3: Online team meeting | B3: https://tu-berlin.zoom-x.de/j/66460442542?pwd=6JDdHFzvrTj3bJokdNJSYxHA3b8F6r.1
A5: Production system (if any) | B5: TBD
A6: Test system (if any) | B6: TBD
A8: GitHub repository | B8: https://github.com/amosproj/amos2025ws02-backup-cluster-manager
A9: GitHub feature board | B9: https://github.com/orgs/amosproj/projects/90
A10: GitHub imp-squared backlog | B10: https://github.com/orgs/amosproj/projects/94
A12: Team T-shirt (white) | B12: https://www.shirtinator.de/s/WGBu8LkSRqOJZe-LDXqisw
A13: Team T-shirt (black) | B13: https://www.shirtinator.de/s/jG2py-QWSDeg3IraRTb-bQ
A15: Additional materials
A16: Discord | B16: https://discord.gg/mhFBrsTx
A17: Figma Link Website | B17: https://www.figma.com/design/kLihICBMvBVKCodv1OlY4Y/Website-Design?m=auto&t=UItPz3hhwCtSgsc5-1
A19: Team maling list | B19: oss-amos-proj2@lists.fau.de

Sheet Project Team
A1: Last Name | B1: First Name | C1: GitHub User Name | D1: Email Address
A2: Wysokinska | B2: Xemena | C2: xenia1w | D2: xenia.wysokinska@gmail.com
A3: Ostrizki | B3: Jan | C3: Stringrimm | D3: jan.ostrizki@fau.de
A4: Raju | B4: Robin Jose | C4: robinrj6 | D4: robin.jose.raju@fau.de
A5: Nogu | B5: Ervin | C5: ervinn09 | D5: ervin.nogu@campus.tu-berlin.de
A6: Krüger | B6: Landolf | C6: krueger-hash | D6: l.krueger.1@campus.tu-berlin.de
A7: Tröger | B7: Nicolas | C7: fe27hity | D7: nico.troeger@fau.de
A8: Killer | B8: Hans | C8: HansKiller-TH | D8: hanskiller@web.de
A9: Schulze | B9: Levin | C9: p0d3x

Sheet Role Assignments
C1: Product Owner
A2: # | B2: Meeting Day | C2: Review | D2: Planning | E2: Software Developer | F2: Release Manager | G2: Scrum Master | H2: Comment
A3: 0 | B3: 45945 | C3: - | D3: - | E3: Everyone else | F3: - | G3: Xemena Wysokinska | H3: First Meeting
A4: 1 | B4: =B3+7 -> 45952 | C4: Jan Ostrizki | D4: Levin Schulze | E4: Everyone else | F4: - | G4: Xemena Wysokinska
A5: 2 | B5: =B4+7 -> 45959 | C5: Levin Schulze | D5: Jan Ostrizki | E5: Everyone else | F5: Nicolas Tröger | G5: Xemena Wysokinska
A6: 3 | B6: =B5+7 -> 45966 | C6: Jan Ostrizki | D6: Levin Schulze | E6: Everyone else | F6: Hans Killer | G6: Xemena Wysokinska | H6: Build Process Review
A7: 4 | B7: =B6+7 -> 45973 | C7: Levin Schulze | D7: Jan Ostrizki | E7: Everyone else | F7: Robin Rose Raju | G7: Xemena Wysokinska
A8: 5 | B8: =B7+7 -> 45980 | C8: Jan Ostrizki | D8: Levin Schulze | E8: Everyone else | F8: Ervin Nogu | G8: Xemena Wysokinska
A9: 6 | B9: =B8+7 -> 45987 | C9: Levin Schulze | D9: Jan Ostrizki | E9: Everyone else | F9: Landolf Krüger | G9: Xemena Wysokinska | H9: Mid-term due
A10: 7 | B10: =B9+7 -> 45994 | C10: Jan Ostrizki | D10: Levin Schulze | E10: Everyone else | F10: Nicolas Tröger | G10: Xemena Wysokinska
A11: 8 | B11: =B10+7 -> 46001 | C11: Levin Schulze | D11: Jan Ostrizki | E11: Everyone else | F11: Hans Killer | G11: Xemena Wysokinska
A12: 9 | B12: =B11+7 -> 46008 | C12: Jan Ostrizki | D12: Levin Schulze | E12: Everyone else | F12: Robin Rose Raju | G12: Xemena Wysokinska
A13: 10 | B13: 46029 | C13: Jan Ostrizki | D13: Jan Ostrizki | E13: Everyone else | F13: Ervin Nogu | G13: Xemena Wysokinska
A14: 11 | B14: =B13+7 -> 46036 | C14: Jan Ostrizki | D14: Levin Schulze | E14: Everyone else | F14: Landolf Krüger | G14: Xemena Wysokinska
A15: 12 | B15: =B14+7 -> 46043 | C15: Levin Schulze | D15: Jan Ostrizki | E15: Everyone else | F15: Nicolas Tröger | G15: Xemena Wysokinska
A16: 13 | B16: =B15+7 -> 46050 | C16: Jan Ostrizki | D16: Levin Schulze | E16: Everyone else | F16: Hans Killer | G16: Xemena Wysokinska
A17: 14 | B17: =B16+7 -> 46057 | C17: Levin Schulze | D17: Jan Ostrizki | E17: Everyone else | F17: Robin Rose Raju | G17: Xemena Wysokinska | H17: Demo day!
A19: Product owners, software developers, and Scurm Master are set and ideally don't change over time; the critical part is the Release Manager role you need to define here

Sheet Team Contract
A1: Goals
B2: Fulfill the needs of our customer (SEP) Working Prototype Good team experience Learn more/Gaining experience about working agile Sharing knowledge among each other Transparent culture & good communication Learn how to open-source
A3: Meeting norms
B4: Weeklies: At 12:30 on Wednesday on Zoom (https://tu-berlin.zoom-x.de/j/66460442542?pwd=6JDdHFzvrTj3bJokdNJSYxHA3b8F6r.1) 90 mins. Weekly/Bi-Weekly Sync with SEP On time, give notice if someone can’t make/with delay Raising hands for better communication flow in bigger meetings like e.g. weekly
A5: Working norms | B5: Working norms
B6: Developers have a cutoff day a before at noon Revert if MR if it breaks other code and if there is no time for a fix Use a CI build/test pipeline MR with random reviewer (preferably a nominated one)
A7: Coordination norms
B8: Coordination over Discord (https://discord.gg/mhFBrsTx) Inform others if you can’t work temporarily
A9: Communication norms
B10: Communication over mainly on Discord, Email as emergency/backup option Weekly meeting over Zoom Use webcams as possible Special channels for different groups and topics
A11: Consideration norms
B12: Polite, supportive, respectful, forward, formal & constructive communication English if at least one nonnative speaker present
A13: Cont. improvement norms
B14: Try to help each other Actional item in retro to improve the team Adapt CI and work along it. Do not try to bypass it. Additional channel on Discord if someone needs help
A15: Rewards
B16: Filters on Zoom (SFW!!) Small tokens
A17: Sanctions
B18: Not allowed to use video filters or wear a weird hat Review one additional PR Problems require intervention worst case with professor
A19: Signatures
A21: Scrum Master | B21: Xemena Wysokinska
A22: Product owner | B22: Levin Schulze
A23: Product owner | B23: Jan Ostrizki
A24: Software developer | B24: Robin Jose Raju
A25: Software developer | B25: Ervin Nogu
A26: Software developer | B26: Landolf Krüger
A27: Software developer | B27: Nicolas Tröger
A28: Software developer | B28: Hans Killer
A29: Software developer

Sheet Product Goal
A1: Product Vision | B1: Project Mission
A3: The Backup Cluster Manager software introduces a distributed approach into a system currently consisting of unconnected nodes . The software should demonstrate the benefits of a distributed approach, and should mirror real life use-cases and scenarios, and the effectiveness of using this approach. By using springboot, it can be easily integrated, and used as basis for enterprise projects while offering a user friendly UI built with Angular & TailwindCSS. | B3: Creating an MVP for our industry partner which implements an alternative approach for managing distributed nodes. It offers an UI for editing and overview data from nodes as well as users and their permissions. The backend simulates backup nodes and how nodes will interact with each other. Frontend communicates with the backend to get/edit/delete data such as users, permissions as well as backups & cluster information.

Sheet Product Glossary
A1: Term | B1: Definition
A2: Cluster Manager | B2: Supervisor instance that manages a set of SEP Sesam server nodes, handles registration of nodes, manipulation and synchronization of e.g. users, groups, and permissions or other meta data. Provides a REST interface for the Frontend and proxies requests to other nodes
A3: SEP Sesam | B3: SEP's Backup and Recovery software product, backups and restores are managed by a SEP Sesam Server
A4: SEP Sesam Server Node, Node | B4: Instance of SEP Sesam Server which shall be part of the cluster
A5: Cluster Mode | B5: Configuration flag on a node, indicating the node should join a cluster. In this mode, permissions and users shall be managed by the cluster manager
A6: Supervisor Instance | B6: Synonymous with Cluster Manager
A7: Node Registration | B7: Process of adding a node to a cluster
A8: User / Group | B8: Authenticated principals that can be created, modified and assigned permissions.
A9: Client | B9: A system that should be backed up by an SEP Sesam Server (e.g. a person's laptop computer)
A10: Frontend, FE | B10: The primary web UI, which runs in the browser and communicates with the CM's REST endpoints (directly, or via proxy, LB, etc TBD)
A11: Synchronization Process | B11: The mechanism of propagating information, such as users, groups, or permissions to downstream nodes
A12: Proxy Functionality | B12: The ability of issuing requests or listing data from a node via the CM's REST API
... A18: Backup User | B18: System users who can create backups, no access to user management

Sheet Sprint Goals
A1: Sprint # | B1: Sprint goal
A2: 1 | B2: None
A3: =A2+1 -> 2 | B3: None
A4: =A3+1 -> 3 | B4: None
A5: =A4+1 -> 4 | B5: Working MVP with FE, CM and 2 Nodes
A6: =A5+1 -> 5 | B6: Working MVP with FE, CM and 2 Nodes
A7: =A6+1 -> 6 | B7: Mid-Project Release
A8: =A7+1 -> 7 | B8: Working Backup Schedules and Mock Tasks
A9: =A8+1 -> 8 | B9: Working Permissions / User Groups + Bulk Data
A10: =A9+1 -> 9 | B10: Advanced Cluster Management
A11: =A10+1 -> 10 | B11: Advanced Cluster Management Pt2
A12: =A11+1 -> 11 | B12: Groups/Permissions + Webflux
A13: =A12+1 -> 12 | B13: Polishing + Metrics
A14: =A13+1 -> 13 | B14: QA/Fixing
A15: =A14+1 -> 14 | B15: Final Project Release

Sheet Velocity Tracking
A1: Sprint # | B1: Story Points Realized | C1: Story Points Committed | D1: Average Story Points Realized
A2: 1 | B2: ='Final Project Release plan'!F9 -> 0 | C2: ='Final Project Release plan'!D9 -> 2 | D2: =AVERAGE('Velocity Tracking'!$B$2:$B$10) -> 14.777778
A3: =A2+1 -> 2 | B3: ='Final Project Release plan'!F10 -> 13 | C3: ='Final Project Release plan'!D10 -> 15 | D3: =AVERAGE('Velocity Tracking'!$B$2:$B$10) -> 14.777778
A4: =A3+1 -> 3 | B4: ='Final Project Release plan'!F11 -> 14 | C4: ='Final Project Release plan'!D11 -> 21 | D4: =AVERAGE('Velocity Tracking'!$B$2:$B$10) -> 14.777778
A5: =A4+1 -> 4 | B5: ='Final Project Release plan'!F12 -> 20 | C5: ='Final Project Release plan'!D12 -> 29 | D5: =AVERAGE('Velocity Tracking'!$B$2:$B$10) -> 14.777778
A6: =A5+1 -> 5 | B6: ='Final Project Release plan'!F13 -> 20 | C6: ='Final Project Release plan'!D13 -> 18 | D6: =AVERAGE('Velocity Tracking'!$B$2:$B$10) -> 14.777778
A7: =A6+1 -> 6 | B7: ='Final Project Release plan'!F14 -> 20 | C7: ='Final Project Release plan'!D14 -> 18 | D7: =AVERAGE('Velocity Tracking'!$B$2:$B$10) -> 14.777778
A8: =A7+1 -> 7 | B8: ='Final Project Release plan'!F15 -> 16 | C8: ='Final Project Release plan'!D15 -> 20 | D8: =AVERAGE('Velocity Tracking'!$B$2:$B$10) -> 14.777778
A9: =A8+1 -> 8 | B9: ='Final Project Release plan'!F16 -> 4 | C9: ='Final Project Release plan'!D16 -> 7 | D9: =AVERAGE('Velocity Tracking'!$B$2:$B$10) -> 14.777778
A10: =A9+1 -> 9 | B10: ='Final Project Release plan'!F17 -> 26 | C10: ='Final Project Release plan'!D17 -> 20 | D10: =AVERAGE('Velocity Tracking'!$B$2:$B$10) -> 14.777778
A11: =A10+1 -> 10 | B11: ='Final Project Release plan'!F18 -> 15 | C11: 15 | D11: =AVERAGE('Velocity Tracking'!$B$2:$B$10) -> 14.777778
A12: =A11+1 -> 11 | B12: ='Final Project Release plan'!F19
A13: =A12+1 -> 12 | B13: ='Final Project Release plan'!F20
A14: =A13+1 -> 13 | B14: ='Final Project Release plan'!F21
A15: =A14+1 -> 14 | B15: ='Final Project Release plan'!F22
A16: =A15+1 -> 15 | B16: ='Final Project Release plan'!F23 | C16: ='Final Project Release plan'!D23
B18: PLEASE CREATE THE VELOCITY CHART ON A NEW TAB USING THE DATA FROM THIS TAB

Sheet Velocity Chart
A1: Sprint | B1: Average Speed
A2: 2 | B2: =AVERAGE('Velocity Tracking'!B3) -> 13
A3: 3 | B3: =AVERAGE('Velocity Tracking'!B3:B4) -> 13.5
A4: 4 | B4: =AVERAGE('Velocity Tracking'!B3:B5) -> 15.666667
A5: 5 | B5: =AVERAGE('Velocity Tracking'!B3:B6) -> 16.75
A6: 6 | B6: =AVERAGE('Velocity Tracking'!B3:B7) -> 17.4
A7: 7 | B7: =AVERAGE('Velocity Tracking'!B3:B8) -> 17.166667
A8: 8 | B8: =AVERAGE('Velocity Tracking'!B3:B9) -> 15.285714
A9: 9 | B9: =AVERAGE('Velocity Tracking'!B3:B10) -> 16.625
A10: 10 | B10: =AVERAGE('Velocity Tracking'!B3:B11) -> 16.444444
A11: 11 | B11: =AVERAGE('Velocity Tracking'!B3:B12) -> 16.444444
A12: 12 | B12: =AVERAGE('Velocity Tracking'!B3:B13) -> 16.444444
A13: 13 | B13: =AVERAGE('Velocity Tracking'!B3:B14) -> 16.444444
A14: 14 | B14: =AVERAGE('Velocity Tracking'!B3:B15) -> 16.444444
A15: 15 | B15: =AVERAGE('Velocity Tracking'!B3:B16) -> 16.444444

Sheet Mid-Project Release plan
A1: Sprint | B1: Goal | C1: Feature Name | D1: Est. size | E1: Est. remaining | F1: Real size | G1: Real remaining
A3: Release
A5: Total | D5: =sum(D8:D14) -> 95 | E5: =D5 -> 95
A7: Sprints
E8: Estimated burn-down | G8: Real burn-down
A9: 1 | B9: ='Sprint Goals'!B2 -> None | D9: =sum(D21:D22) -> 2 | E9: =$D$5 -> 95 | F9: =SUM(F20:F22) -> 0 | G9: =$D$5 -> 95
A10: =A9+1 -> 2 | B10: ='Sprint Goals'!B3 -> None | D10: =SUM(D24:D30) -> 15 | E10: =E9-D9 -> 93 | F10: =SUM(F24:F30) -> 13 | G10: =G9-F9 -> 95
A11: =A10+1 -> 3 | B11: ='Sprint Goals'!B4 -> None | D11: =SUM(D32:D39) -> 21 | E11: =E10-D10 -> 78 | F11: 14 | G11: =G10-F10 -> 82
A12: 4 | B12: ='Sprint Goals'!B5 -> Working MVP with FE, CM and 2 Nodes | D12: =SUM(D41:D51) -> 21 | E12: =E11-D11 -> 57 | F12: =SUM(F41:F51) -> 20 | G12: =G11-F11 -> 68
A13: 5 | B13: ='Sprint Goals'!B6 -> Working MVP with FE, CM and 2 Nodes | D13: =SUM(D53:D66) -> 18 | E13: =E12-D12 -> 36 | F13: =SUM(F53:F66) -> 20 | G13: =G12-F12 -> 48
A14: 6 | B14: ='Sprint Goals'!B7 -> Mid-Project Release | D14: =SUM(D68:D77) -> 18 | E14: =E13-D13 -> 18 | F14: =SUM(F68:F77) -> 20 | G14: =G13-F13 -> 28
A18: Features
A20: =A9 -> 1 | B20: ='Sprint Goals'!B2 -> None
C21: Deciding our Tshirt design | D21: 1 | F21: 0
C22: Deciding our team logo | D22: 1 | F22: 0
A23: =A10 -> 2 | B23: ='Sprint Goals'!B3 -> None
C24: Deciding our Tshirt design | D24: 1 | F24: 1
C25: Setup Build Process for Backend | D25: 3 | F25: 2
C26: Setup Basic Angular Project (Frontend) | D26: 2 | F26: 2
C27: Create first architecture draft | D27: 3 | F27: 3
C28: Setup Build Process For Frontend | D28: 3 | F28: 2
C29: Create Basic Spring Boot Project | D29: 2 | F29: 2
C30: Deciding our team logo | D30: 1 | F30: 1
A31: 3 | B31: ='Sprint Goals'!B4 -> None
C32: Define entities for DBs | D32: 3 | F32: 3
C33: Create Docker Compose Configuration | D33: 3 | F33: 2
C34: Setup Database and Integrate it | D34: 2 | F34: 1
C35: Setup Dockerfile (Backend) | D35: 3 | F35: 2
C36: Create Basic UI Layout | D36: 3 | F36: 2
C37: Create Overview page | D37: 3 | F37: 3
C38: Add functionallity to sidebar | D38: 1 | F38: 1
C39: Create multiple pages for Router Outlet | D39: 3 | F39: 2
A40: 4 | B40: ='Sprint Goals'!B5 -> Working MVP with FE, CM and 2 Nodes
C41: Backend: Create Cluster Manager | D41: 3 | F41: 3
C42: Frontend: Create Node Tab | D42: 3 | F42: 3
C43: Backend: Get Nodes API | D43: 3 | F43: 3
C44: Backend: Get Backups API | D44: 3 | F44: 3
C45: Frontend: Create Backups Tab | D45: 3 | F45: 3
C46: Frontend: Header moving while scrolling | D46: 0 | F46: 0
C47: Add Jacoco To Build And Integrate As Badge | D47: 3 | F47: 2
...

Sheet Burn-down Chart (Mid-Project)
A1: Burn-Down Chart
A2: ='Mid-Project Release plan'!D5 -> 95 | B2: ='Velocity Chart'!B5 -> 16.75
A3: =A2-B2 -> 78.25 | B3: ='Velocity Chart'!B6 -> 17.4
A4: =A3-B3 -> 60.85 | B4: ='Velocity Chart'!B7 -> 17.166667
A5: =A4-B4 -> 43.683333 | B5: ='Velocity Chart'!B8 -> 15.285714
A6: =A5-B5 -> 28.397619 | B6: ='Velocity Chart'!B9 -> 16.625
A7: =A6-B6 -> 11.772619 | B7: ='Velocity Chart'!B10 -> 16.444444
A8: =A7-B7 -> -4.6718254 | B8: ='Velocity Chart'!B11 -> 16.444444

Sheet Final Project Release plan
A1: Sprint | B1: Goal | C1: Feature Name | D1: Est. size | E1: Est. remaining | F1: Real size | G1: Real remaining
A3: Release
A5: Total | D5: =sum(D9:D22) -> 216 | E5: =D5 -> 216
A7: Sprints
E8: Estimated burn-down | G8: Real burn-down
A9: 1 | B9: ='Sprint Goals'!B2 -> None | D9: =sum(D28:D29) -> 2 | E9: =$D$5 -> 216 | F9: =SUM(F27:F29) -> 0 | G9: =$D$5 -> 216
A10: =A9+1 -> 2 | B10: ='Sprint Goals'!B3 -> None | D10: =SUM(D31:D37) -> 15 | E10: =E9-D9 -> 214 | F10: =SUM(F31:F37) -> 13 | G10: =G9-F9 -> 216
A11: =A10+1 -> 3 | B11: ='Sprint Goals'!B4 -> None | D11: =SUM(D39:D46) -> 21 | E11: =E10-D10 -> 199 | F11: 14 | G11: =G10-F10 -> 203
A12: =A11+1 -> 4 | B12: ='Sprint Goals'!B5 -> Working MVP with FE, CM and 2 Nodes | D12: =SUM(D48:D58) -> 29 | E12: =E11-D11 -> 178 | F12: =SUM(F48:F58) -> 20 | G12: =G11-F11 -> 189
A13: =A12+1 -> 5 | B13: ='Sprint Goals'!B6 -> Working MVP with FE, CM and 2 Nodes | D13: =SUM(D60:D73) -> 18 | E13: =E12-D12 -> 149 | F13: =SUM(F60:F73) -> 20 | G13: =G12-F12 -> 169
A14: =A13+1 -> 6 | B14: ='Sprint Goals'!B7 -> Mid-Project Release | D14: =SUM(D75:D84) -> 18 | E14: =E13-D13 -> 131 | F14: =SUM(F75:F84) -> 20 | G14: =G13-F13 -> 149
A15: =A14+1 -> 7 | B15: ='Sprint Goals'!B8 -> Working Backup Schedules and Mock Tasks | D15: =SUM(D86:D90) -> 20 | E15: =E14-D14 -> 113 | F15: =SUM(F86:F90) -> 16 | G15: =G14-F14 -> 129
A16: =A15+1 -> 8 | B16: ='Sprint Goals'!B9 -> Working Permissions / User Groups + Bulk Data | D16: =SUM(D92:D97) -> 7 | E16: =E15-D15 -> 93 | F16: =SUM(F92:F97) -> 4 | G16: =G15-F15 -> 113
A17: =A16+1 -> 9 | B17: ='Sprint Goals'!B10 -> Advanced Cluster Management | D17: =SUM(D99:D103) -> 20 | E17: =E16-D16 -> 86 | F17: =SUM(F99:F103) -> 26 | G17: =G16-F16 -> 109
A18: =A17+1 -> 10 | B18: ='Sprint Goals'!B11 -> Advanced Cluster Management Pt2 | D18: =SUM(D105:D107) -> 13 | E18: =E17-D17 -> 66 | F18: =SUM(F105:F107) -> 15 | G18: =G17-F17 -> 83
A19: =A18+1 -> 11 | B19: ='Sprint Goals'!B12 -> Groups/Permissions + Webflux | D19: =SUM(D109:D112) -> 21
A20: =A19+1 -> 12 | B20: ='Sprint Goals'!B13 -> Polishing + Metrics | D20: =SUM(D117:D119) -> 19
A21: =A20+1 -> 13 | B21: ='Sprint Goals'!B14 -> QA/Fixing | D21: =SUM(D122) -> 13
A22: =A21+1 -> 14 | B22: ='Sprint Goals'!B15 -> Final Project Release | D22: 0
B23: ='Sprint Goals'!B16
A25: Features
A27: =A9 -> 1 | B27: ='Sprint Goals'!B2 -> None
C28: Deciding our Tshirt design | D28: 1 | F28: 0
C29: Deciding our team logo | D29: 1 | F29: 0
A30: =A10 -> 2 | B30: ='Sprint Goals'!B3 -> None
C31: Deciding our Tshirt design | D31: 1 | F31: 1
C32: Setup Build Process for Backend | D32: 3 | F32: 2
C33: Setup Basic Angular Project (Frontend) | D33: 2 | F33: 2
C34: Create first architecture draft | D34: 3 | F34: 3
C35: Setup Build Process For Frontend | D35: 3 | F35: 2
C36: Create Basic Spring Boot Project | D36: 2 | F36: 2
C37: Deciding our team logo | D37: 1 | F37: 1
A38: 3 | B38: ='Sprint Goals'!B4 -> None
C39: Define entities for DBs | D39: 3 | F39: 3
C40: Create Docker Compose Configuration | D40: 3 | F40: 2
C41: Setup Database and Integrate it | D41: 2 | F41: 1
C42: Setup Dockerfile (Backend) | D42: 3 | F42: 2
C43: Create Basic UI Layout | D43: 3 | F43: 2
C44: Create Overview page | D44: 3 | F44: 3
C45: Add functionallity to sidebar | D45: 1 | F45: 1
...

Sheet Burn-down Chart (Final Release)
A1: Burn-Down Chart
A2: ='Final Project Release plan'!D5 -> 216 | B2: ='Velocity Chart'!B5 -> 16.75
A3: =A2-B2 -> 199.25 | B3: ='Velocity Chart'!B6 -> 17.4
A4: =A3-B3 -> 181.85 | B4: ='Velocity Chart'!B7 -> 17.166667
A5: =A4-B4 -> 164.68333 | B5: ='Velocity Chart'!B8 -> 15.285714
A6: =A5-B5 -> 149.39762 | B6: ='Velocity Chart'!B9 -> 16.625
A7: =A6-B6 -> 132.77262 | B7: ='Velocity Chart'!B10 -> 16.444444
A8: =A7-B7 -> 116.32817 | B8: ='Velocity Chart'!B11 -> 16.444444
A9: =A8-B8 -> 99.88373 | B9: ='Velocity Chart'!B12 -> 16.444444
A10: =A9-B9 -> 83.439286 | B10: ='Velocity Chart'!B13 -> 16.444444
A11: =A10-B10 -> 66.994841 | B11: ='Velocity Chart'!B14 -> 16.444444
A12: =A11-B11 -> 50.550397 | B12: ='Velocity Chart'!B15 -> 16.444444
B13: ='Velocity Chart'!B16

Sheet Definition of Done
A1: # | B1: Feature Definition of Done | C1: Sprint Release Definition of Done | D1: Project Release Definition of Done
B2: Code review has been completed and code has been merged | C2: Project builds, deploys, and tests successfully | D2: Project can be opened on desktop browsers
B3: All feature branches have been merged and closed | C3: Database update scripts succeed, consistency tests pass | D3: Design documentation has been updated
B4: New feature code has been documented | C4: Sprint release notes have been written | D4: User documentation has been updated
B5: Component tests have been written and pass | C5: Change log has been updated | D5: The backend simulation must succeed and produce an artifact.
B6: Component builds with build pipeline | C6: BOM is updated | D6: The frontend should be able to handle user inputs & send them to the backend
B7: Fulfills all acceptance criteria for item

Sheet Documentation
A1: Type | B1: Link / reference

Sheet Bill of Materials
A1: # | B1: Context | C1: Name | D1: Version | E1: License | F1: Comment
A2: 1 | B2: Frontend | C2: Tailwindcss | D2: 4.1.16 | E2: MIT License | F2: Utility-first CSS Framework
A3: 2 | B3: Frontend | C3: Flowbite | D3: 3.1.2 | E3: MIT License | F3: Component library built on Tailwind CSS.
A4: 3 | B4: Frontend | C4: Angular | D4: 20.3.7 | E4: MIT License
A5: 4 | B5: Frontend | C5: typescript | D5: 5.9.3 | E5: Apache-2.0
A6: 5 | B6: Frontend | C6: zonejs | D6: 0.15.1 | E6: MIT License
A7: 6 | B7: Frontend | C7: tslib | D7: 2.8.1 | E7: MIT License
A8: 7 | B8: Frontend | C8: karma | D8: 6.4.4 | E8: MIT License
A9: 8 | B9: Frontend | C9: karma-chrome-launcher | D9: 3.2.0 | E9: MIT License
A10: 9 | B10: Frontend | C10: karma-coverage | D10: 2.2.1 | E10: MIT License
A11: 10 | B11: Frontend | C11: karma-jasmine | D11: 5.1.0 | E11: MIT License
A12: 11 | B12: Frontend | C12: karma-jasmine-html-reporter | D12: 2.1.0 | E12: MIT License
A13: 12 | B13: Frontend | C13: postcss | D13: 8.5.6 | E13: MIT License
A14: 13 | B14: Frontend | C14: rxjs | D14: 7.8.2 | E14: Apache-2.0
A15: 14 | B15: Backend | C15: postgresql(-docker) | D15: latest | E15: MIT
... A21: 20 | B21: Backend | C21: Lombok | D21: latest | E21: MIT

Sheet Planning Poker
A1: ='Project Team'!A1 -> Last Name | B1: ='Project Team'!B1 -> First Name | C1: Value
A2: ='Project Team'!A2 -> Wysokinska | B2: ='Project Team'!B2 -> Xemena | E2: =average(C2:C10) -> 4.6 | F2: =if(stdev(C2:C5) > 0,"NOK", "OK") -> OK
A3: ='Project Team'!A3 -> Ostrizki | B3: ='Project Team'!B3 -> Jan
A4: ='Project Team'!A4 -> Raju | B4: ='Project Team'!B4 -> Robin Jose | C4: 5
A5: ='Project Team'!A5 -> Nogu | B5: ='Project Team'!B5 -> Ervin | C5: 5
A6: ='Project Team'!A6 -> Krüger | B6: ='Project Team'!B6 -> Landolf | C6: 5 | E6: 0 | F6: No size
A7: ='Project Team'!A7 -> Tröger | B7: ='Project Team'!B7 -> Nicolas | C7: 3 | E7: 1 | F7: Trivial size
A8: =#REF! -> #REF! | B8: =#REF! -> #REF! | E8: 2 | F8: Small size
A9: ='Project Team'!A8 -> Killer | B9: ='Project Team'!B8 -> Hans | C9: 5 | E9: 3 | F9: Medium size
A10: ='Project Team'!A9 -> Schulze | B10: ='Project Team'!B9 -> Levin | E10: 5 | F10: Large size
E11: 8 | F11: Very large size
E12: 13 | F12: Too large (size)
A14: How to play planning poker
A16: 1. Everyone type their number into their value field, don't hit return yet
A17: 2. Someone, perhaps a product owner, count down 3.. 2.. 1..
A18: 3. Then, everyone hit return to submit their value
